<?xml version="1.0"?>
<robot name="wheel" xmlns:xacro="http://www.ros.org/wiki/xacro">

  <!-- side: left, right -->
  <!-- flip: left=1, right=-1 -->
  <xacro:macro name="wheel" params="prefix side parent flip">

    <link name="${prefix}${side}_wheel_link">
      <visual>
        <origin xyz="0 0 0" rpy="0 0 0"/>
        <geometry>
          <cylinder length="${wheel_length}" radius="${wheel_radius}"/>
        </geometry>
          <material name="black"/>
      </visual>

      <collision>
        <origin xyz="0 0 0" rpy="${PI/2} 0 0"/>
        <geometry>
          <cylinder length="${wheel_length}" radius="${wheel_radius}"/>
        </geometry>
          <material name="black"/>
      </collision>

      <inertial>
        <origin xyz="0 0 0" rpy="${PI/2} 0 0"/>
        <mass value="${wheel_mass}"/>
        <inertia
          ixx="${wheel_mass / 12.0 * (3*wheel_radius*wheel_radius + wheel_length*wheel_length)}" ixy="0.0" ixz="0.0"
          iyy="${wheel_mass / 12.0 * (3*wheel_radius*wheel_radius + wheel_length*wheel_length)}" iyz="0.0"
          izz="${wheel_mass / 2.0 * wheel_radius*wheel_radius}"/>
      </inertial>
    </link>
    
    <joint name="${prefix}${side}_wheel_joint" type="continuous">
        <parent link="${prefix}${parent}" />
        <child link="${prefix}${side}_wheel_link" />
        <origin xyz="0.0 0.0 0.0" />
        <axis xyz="0 1 0" />
    </joint>


  </xacro:macro>
</robot> 